Workbook

Sheet Dashboard
A1: DASHBOARD DE GESTIÓN Y CARTA GANTT
A3: Control integrado de tareas administrativas, compras públicas, inventario, bodega, prevención y otros procesos
A5: ="TOTAL REGISTROS"&CHAR(10)&TEXT(COUNTIF('Plan de Tareas'!A2:A301,"<>"),"0") -> TOTAL REGISTROS 10 | D5: ="EN CURSO"&CHAR(10)&TEXT(COUNTIF('Plan de Tareas'!I2:I301,"En curso"),"0") -> EN CURSO 3 | G5: ="TERMINADAS"&CHAR(10)&TEXT(COUNTIF('Plan de Tareas'!I2:I301,"Terminada")+COUNTIF('Plan de Tareas'!I2:I301,"Completada"),"0") -> TERMINADAS 2 | J5: ="ALERTAS ROJAS"&CHAR(10)&TEXT(COUNTIF('Plan de Tareas'!P2:P301,"ROJO"),"0") -> ALERTAS ROJAS 0
A9: Indicador | B9: Valor | C9: Meta/Referencia | E9: Estado | F9: Cantidad
A10: Avance promedio | B10: =IFERROR(SUMIF('Plan de Tareas'!B2:B301,"PROCESO",'Plan de Tareas'!M2:M301)/COUNTIF('Plan de Tareas'!B2:B301,"PROCESO"),0) -> 0.25 | C10: ≥ 80% | E10: No iniciada | F10: =COUNTIF('Plan de Tareas'!I2:I301,E10) -> 5
A11: Tareas críticas | B11: =COUNTIF('Plan de Tareas'!H2:H301,"Crítica") -> 3 | C11: 0 vencidas | E11: En curso | F11: =COUNTIF('Plan de Tareas'!I2:I301,E11) -> 3
A12: Próximas 7 días | B12: =COUNTIFS('Plan de Tareas'!A2:A301,"<>",'Plan de Tareas'!K2:K301,">="&TODAY(),'Plan de Tareas'!K2:K301,"<="&TODAY()+7,'Plan de Tareas'!I2:I301,"<>Terminada",'Plan de Tareas'!I2:I301,"<>Completada") -> 1 | C12: Gestionar | E12: En espera | F12: =COUNTIF('Plan de Tareas'!I2:I301,E12) -> 0
A13: Compras públicas activas | B13: =COUNTIFS('Plan de Tareas'!R2:R301,"<>",'Plan de Tareas'!I2:I301,"<>Completada",'Plan de Tareas'!I2:I301,"<>Cancelada") -> 8 | C13: Seguimiento | E13: Bloqueada | F13: =COUNTIF('Plan de Tareas'!I2:I301,E13) -> 0
E14: Terminada | F14: =COUNTIF('Plan de Tareas'!I2:I301,E14) -> 0
E15: Completada | F15: =COUNTIF('Plan de Tareas'!I2:I301,E15) -> 2
A16: Prioridad | B16: Cantidad | E16: Cancelada | F16: =COUNTIF('Plan de Tareas'!I2:I301,E16) -> 0
A17: Crítica | B17: =COUNTIF('Plan de Tareas'!H2:H301,A17) -> 3
A18: Alta | B18: =COUNTIF('Plan de Tareas'!H2:H301,A18) -> 6
A19: Media | B19: =COUNTIF('Plan de Tareas'!H2:H301,A19) -> 1
A20: Baja | B20: =COUNTIF('Plan de Tareas'!H2:H301,A20) -> 0
A23: ALERTAS EJECUTIVAS
A24: Alerta | B24: Cantidad | C24: Acción | E24: SEMÁFORO GENERAL
A25: Atrasadas | B25: =COUNTIF('Plan de Tareas'!O2:O301,"ATRASAD*") -> 0 | C25: Regularizar / reprogramar | E25: ROJO | F25: =COUNTIF('Plan de Tareas'!P2:P301,"ROJO") -> 0
A26: Urgentes (≤3 días) | B26: =COUNTIF('Plan de Tareas'!O2:O301,"URGENTE") -> 0 | C26: Prioridad inmediata | E26: AMARILLO | F26: =COUNTIF('Plan de Tareas'!P2:P301,"AMARILLO") -> 1
A27: Próximas (4–7 días) | B27: =COUNTIF('Plan de Tareas'!O2:O301,"PROXIM*") -> 1 | C27: Preparar gestión | E27: VERDE | F27: =COUNTIF('Plan de Tareas'!P2:P301,"VERDE") -> 9
A28: Bloqueadas | B28: =COUNTIF('Plan de Tareas'!O2:O301,"BLOQUEADA") -> 0 | C28: Resolver dependencia
A29: Procesos sin etapas | B29: =COUNTIF('Plan de Tareas'!O2:O301,"SIN ETAPAS") -> 0 | C29: Definir etapas
A30: PRÓXIMOS HITOS / VENCIMIENTOS
A31: ID | B31: Tarea | C31: Responsable | D31: Término | E31: Días reales | F31: Alerta | G31: Semáforo
A32: ='Plan de Tareas'!A2 -> CP-001 | B32: ='Plan de Tareas'!F2 -> Proceso completo de compra | C32: ='Plan de Tareas'!G2 -> Oscar Arias | D32: ='Plan de Tareas'!K2 -> 46356 | E32: ='Plan de Tareas'!N2 -> 35 | F32: ='Plan de Tareas'!O2 -> SIN ALERTA | G32: ='Plan de Tareas'!P2 -> VERDE
A33: ='Plan de Tareas'!A3 -> CP-001.1 | B33: ='Plan de Tareas'!F3 -> Revisar necesidad y especificaciones | C33: ='Plan de Tareas'!G3 -> Oscar Arias | D33: ='Plan de Tareas'!K3 -> 46322 | E33: ='Plan de Tareas'!N3 -> 0 | F33: ='Plan de Tareas'!O3 -> TERMINADA | G33: ='Plan de Tareas'!P3 -> VERDE
A34: ='Plan de Tareas'!A4 -> CP-001.2 | B34: ='Plan de Tareas'!F4 -> Ver precios y referencias de mercado | C34: ='Plan de Tareas'!G4 -> Oscar Arias | D34: ='Plan de Tareas'!K4 -> 46324 | E34: ='Plan de Tareas'!N4 -> 0 | F34: ='Plan de Tareas'!O4 -> TERMINADA | G34: ='Plan de Tareas'!P4 -> VERDE
A35: ='Plan de Tareas'!A5 -> CP-001.3 | B35: ='Plan de Tareas'!F5 -> Revisar Convenio Marco / Compra Ágil | C35: ='Plan de Tareas'!G5 -> Oscar Arias | D35: ='Plan de Tareas'!K5 -> 46329 | E35: ='Plan de Tareas'!N5 -> 8 | F35: ='Plan de Tareas'!O5 -> SIN ALERTA | G35: ='Plan de Tareas'!P5 -> VERDE
A36: ='Plan de Tareas'!A6 -> CP-001.4 | B36: ='Plan de Tareas'!F6 -> Preparar y aprobar requerimiento | C36: ='Plan de Tareas'!G6 -> Oscar Arias | D36: ='Plan de Tareas'!K6 -> 46332 | E36: ='Plan de Tareas'!N6 -> 11 | F36: ='Plan de Tareas'!O6 -> SIN ALERTA | G36: ='Plan de Tareas'!P6 -> VERDE
A37: ='Plan de Tareas'!A7 -> CP-001.5 | B37: ='Plan de Tareas'!F7 -> Publicar / emitir proceso de compra | C37: ='Plan de Tareas'!G7 -> Compras | D37: ='Plan de Tareas'!K7 -> 46338 | E37: ='Plan de Tareas'!N7 -> 17 | F37: ='Plan de Tareas'!O7 -> SIN ALERTA | G37: ='Plan de Tareas'!P7 -> VERDE
A38: ='Plan de Tareas'!A8 -> CP-001.6 | B38: ='Plan de Tareas'!F8 -> Evaluación y adjudicación | C38: ='Plan de Tareas'!G8 -> Compras | D38: ='Plan de Tareas'!K8 -> 46344 | E38: ='Plan de Tareas'!N8 -> 23 | F38: ='Plan de Tareas'!O8 -> SIN ALERTA | G38: ='Plan de Tareas'!P8 -> VERDE
A39: ='Plan de Tareas'!A9 -> CP-001.7 | B39: ='Plan de Tareas'!F9 -> Emitir y aceptar Orden de Compra | C39: ='Plan de Tareas'!G9 -> Compras | D39: ='Plan de Tareas'!K9 -> 46346 | E39: ='Plan de Tareas'!N9 -> 25 | F39: ='Plan de Tareas'!O9 -> SIN ALERTA | G39: ='Plan de Tareas'!P9 -> VERDE
A40: ='Plan de Tareas'!A10 -> CP-001.8 | B40: ='Plan de Tareas'!F10 -> Despacho, recepción conforme y cierre | C40: ='Plan de Tareas'!G10 -> Oscar Arias | D40: ='Plan de Tareas'!K10 -> 46356 | E40: ='Plan de Tareas'!N10 -> 35 | F40: ='Plan de Tareas'!O10 -> SIN ALERTA | G40: ='Plan de Tareas'!P10 -> VERDE
A41: ='Plan de Tareas'!A11 -> ADM-001 | B41: ='Plan de Tareas'!F11 -> Elaborar informe administrativo mensual | C41: ='Plan de Tareas'!G11 -> Oscar Arias | D41: ='Plan de Tareas'!K11 -> 46325 | E41: ='Plan de Tareas'!N11 -> 4 | F41: ='Plan de Tareas'!O11 -> PROXIMA | G41: ='Plan de Tareas'!P11 -> AMARILLO

Sheet Plan de Tareas
A1: ID | B1: Nivel | C1: ID Proceso Padre | D1: Área / Unidad | E1: Proceso / Proyecto | F1: Etapa / Tarea | G1: Responsable | H1: Prioridad | I1: Estado | J1: Fecha inicio | K1: Fecha término planificada | L1: Duración (días) | M1: % Avance Automático | N1: Días restantes | O1: Alerta | P1: Semáforo | Q1: % Participación automática | R1: Dependencia / Observación | S1: Hito Compra Pública | T1: N° Requerimiento / Licitación / OC | U1: Monto estimado | V1: Proveedor | W1: Próximo hito | X1: Fecha próximo hito | Y1: Riesgo
A2: CP-001 | B2: PROCESO | D2: Bienes y Servicios | E2: Adquisición de insumos | F2: Proceso completo de compra | G2: Oscar Arias | H2: Crítica | I2: En curso | J2: 46321 | K2: 46356 | L2: =IF(A2="","",IF(OR(J2="",K2=""),"",MAX(1,K2-J2+1))) -> 36 | M2: =IF(A2="","",IF(B2="PROCESO",IF(COUNTIF($C$2:$C$301,A2)=0,0,SUMIF($C$2:$C$301,A2,$M$2:$M$301)/COUNTIF($C$2:$C$301,A2)),IF(OR(I2="Terminada",I2="Completada"),1,IF(OR(I2="No iniciada",I2="Cancelada"),0,IF(OR(J2="",K2=""),0,MIN(0.99,MAX(0,(TODAY()-J2+1)/MAX(1,K2-J2+1)))))))) -> 0.25 | N2: =IF(A2="","",IF(K2="","",IF(OR(I2="Terminada",I2="Completada"),0,K2-TODAY()))) -> 35 | O2: =IF(A2="","",IF(B2="PROCESO",IF(COUNTIF($C$2:$C$301,A2)=0,"SIN ETAPAS",IF(M2=1,"TERMINADO",IF(N2<0,"ATRASADO",IF(N2<=3,"URGENTE",IF(N2<=7,"PROXIMO","SIN ALERTA"))))),IF(OR(I2="Terminada",I2="Completada"),"TERMINADA",IF(I2="Bloqueada","BLOQUEADA",IF(N2<0,"ATRASADA",IF(N2<=3,"URGENTE",IF(N2<=7,"PROXIMA","SIN ALERTA"))))))) -> SIN ALERTA | P2: =IF(A2="","",IF(OR(I2="Terminada",I2="Completada"),"VERDE",IF(I2="Bloqueada","ROJO",IF(N2<0,"ROJO",IF(N2<=3,"ROJO",IF(N2<=7,"AMARILLO","VERDE")))))) -> VERDE | Q2: =IF(A2="","",IF(OR(B2<>"ETAPA",C2=""),"",1/COUNTIF($C$2:$C$301,C2))) | R2: El proceso llega a 100% sólo cuando sus etapas relacionadas alcanzan el 100%. | T2: REQ-2026-01 | U2: 3500000 | W2: Recepción conforme | X2: 46356 | Y2: Alto
A3: CP-001.1 | B3: ETAPA | C3: CP-001 | D3: Bienes y Servicios | E3: Adquisición de insumos | F3: Revisar necesidad y especificaciones | G3: Oscar Arias | H3: Alta | I3: Completada | J3: 46321 | K3: 46322 | L3: =IF(A3="","",IF(OR(J3="",K3=""),"",MAX(1,K3-J3+1))) -> 2 | M3: =IF(A3="","",IF(B3="PROCESO",IF(COUNTIF($C$2:$C$301,A3)=0,0,SUMIF($C$2:$C$301,A3,$M$2:$M$301)/COUNTIF($C$2:$C$301,A3)),IF(OR(I3="Terminada",I3="Completada"),1,IF(OR(I3="No iniciada",I3="Cancelada"),0,IF(OR(J3="",K3=""),0,MIN(0.99,MAX(0,(TODAY()-J3+1)/MAX(1,K3-J3+1)))))))) -> 1 | N3: =IF(A3="","",IF(K3="","",IF(OR(I3="Terminada",I3="Completada"),0,K3-TODAY()))) -> 0 | O3: =IF(A3="","",IF(B3="PROCESO",IF(COUNTIF($C$2:$C$301,A3)=0,"SIN ETAPAS",IF(M3=1,"TERMINADO",IF(N3<0,"ATRASADO",IF(N3<=3,"URGENTE",IF(N3<=7,"PROXIMO","SIN ALERTA"))))),IF(OR(I3="Terminada",I3="Completada"),"TERMINADA",IF(I3="Bloqueada","BLOQUEADA",IF(N3<0,"ATRASADA",IF(N3<=3,"URGENTE",IF(N3<=7,"PROXIMA","SIN ALERTA"))))))) -> TERMINADA | P3: =IF(A3="","",IF(OR(I3="Terminada",I3="Completada"),"VERDE",IF(I3="Bloqueada","ROJO",IF(N3<0,"ROJO",IF(N3<=3,"ROJO",IF(N3<=7,"AMARILLO","VERDE")))))) -> VERDE | Q3: =IF(A3="","",IF(OR(B3<>"ETAPA",C3=""),"",1/COUNTIF($C$2:$C$301,C3))) -> 0.125 | R3: Etapa inicial | S3: Requerimiento | T3: REQ-2026-01 | W3: Ver precios | X3: 46323 | Y3: Bajo
A4: CP-001.2 | B4: ETAPA | C4: CP-001 | D4: Bienes y Servicios | E4: Adquisición de insumos | F4: Ver precios y referencias de mercado | G4: Oscar Arias | H4: Alta | I4: Completada | J4: 46323 | K4: 46324 | L4: =IF(A4="","",IF(OR(J4="",K4=""),"",MAX(1,K4-J4+1))) -> 2 | M4: =IF(A4="","",IF(B4="PROCESO",IF(COUNTIF($C$2:$C$301,A4)=0,0,SUMIF($C$2:$C$301,A4,$M$2:$M$301)/COUNTIF($C$2:$C$301,A4)),IF(OR(I4="Terminada",I4="Completada"),1,IF(OR(I4="No iniciada",I4="Cancelada"),0,IF(OR(J4="",K4=""),0,MIN(0.99,MAX(0,(TODAY()-J4+1)/MAX(1,K4-J4+1)))))))) -> 1 | N4: =IF(A4="","",IF(K4="","",IF(OR(I4="Terminada",I4="Completada"),0,K4-TODAY()))) -> 0 | O4: =IF(A4="","",IF(B4="PROCESO",IF(COUNTIF($C$2:$C$301,A4)=0,"SIN ETAPAS",IF(M4=1,"TERMINADO",IF(N4<0,"ATRASADO",IF(N4<=3,"URGENTE",IF(N4<=7,"PROXIMO","SIN ALERTA"))))),IF(OR(I4="Terminada",I4="Completada"),"TERMINADA",IF(I4="Bloqueada","BLOQUEADA",IF(N4<0,"ATRASADA",IF(N4<=3,"URGENTE",IF(N4<=7,"PROXIMA","SIN ALERTA"))))))) -> TERMINADA | P4: =IF(A4="","",IF(OR(I4="Terminada",I4="Completada"),"VERDE",IF(I4="Bloqueada","ROJO",IF(N4<0,"ROJO",IF(N4<=3,"ROJO",IF(N4<=7,"AMARILLO","VERDE")))))) -> VERDE | Q4: =IF(A4="","",IF(OR(B4<>"ETAPA",C4=""),"",1/COUNTIF($C$2:$C$301,C4))) -> 0.125 | R4: Comparación referencial | S4: Cotización | T4: REQ-2026-01 | W4: Revisar mecanismo de compra | X4: 46325 | Y4: Bajo
A5: CP-001.3 | B5: ETAPA | C5: CP-001 | D5: Bienes y Servicios | E5: Adquisición de insumos | F5: Revisar Convenio Marco / Compra Ágil | G5: Oscar Arias | H5: Crítica | I5: En curso | J5: 46325 | K5: 46329 | L5: =IF(A5="","",IF(OR(J5="",K5=""),"",MAX(1,K5-J5+1))) -> 5 | M5: =IF(A5="","",IF(B5="PROCESO",IF(COUNTIF($C$2:$C$301,A5)=0,0,SUMIF($C$2:$C$301,A5,$M$2:$M$301)/COUNTIF($C$2:$C$301,A5)),IF(OR(I5="Terminada",I5="Completada"),1,IF(OR(I5="No iniciada",I5="Cancelada"),0,IF(OR(J5="",K5=""),0,MIN(0.99,MAX(0,(TODAY()-J5+1)/MAX(1,K5-J5+1)))))))) -> 0 | N5: =IF(A5="","",IF(K5="","",IF(OR(I5="Terminada",I5="Completada"),0,K5-TODAY()))) -> 8 | O5: =IF(A5="","",IF(B5="PROCESO",IF(COUNTIF($C$2:$C$301,A5)=0,"SIN ETAPAS",IF(M5=1,"TERMINADO",IF(N5<0,"ATRASADO",IF(N5<=3,"URGENTE",IF(N5<=7,"PROXIMO","SIN ALERTA"))))),IF(OR(I5="Terminada",I5="Completada"),"TERMINADA",IF(I5="Bloqueada","BLOQUEADA",IF(N5<0,"ATRASADA",IF(N5<=3,"URGENTE",IF(N5<=7,"PROXIMA","SIN ALERTA"))))))) -> SIN ALERTA | P5: =IF(A5="","",IF(OR(I5="Terminada",I5="Completada"),"VERDE",IF(I5="Bloqueada","ROJO",IF(N5<0,"ROJO",IF(N5<=3,"ROJO",IF(N5<=7,"AMARILLO","VERDE")))))) -> VERDE | Q5: =IF(A5="","",IF(OR(B5<>"ETAPA",C5=""),"",1/COUNTIF($C$2:$C$301,C5))) -> 0.125 | R5: Definir mecanismo procedente | S5: Cotización | T5: REQ-2026-01 | W5: Definir modalidad | X5: 46329 | Y5: Medio
A6: CP-001.4 | B6: ETAPA | C6: CP-001 | D6: Bienes y Servicios | E6: Adquisición de insumos | F6: Preparar y aprobar requerimiento | G6: Oscar Arias | H6: Alta | I6: No iniciada | J6: 46330 | K6: 46332 | L6: =IF(A6="","",IF(OR(J6="",K6=""),"",MAX(1,K6-J6+1))) -> 3 | M6: =IF(A6="","",IF(B6="PROCESO",IF(COUNTIF($C$2:$C$301,A6)=0,0,SUMIF($C$2:$C$301,A6,$M$2:$M$301)/COUNTIF($C$2:$C$301,A6)),IF(OR(I6="Terminada",I6="Completada"),1,IF(OR(I6="No iniciada",I6="Cancelada"),0,IF(OR(J6="",K6=""),0,MIN(0.99,MAX(0,(TODAY()-J6+1)/MAX(1,K6-J6+1)))))))) -> 0 | N6: =IF(A6="","",IF(K6="","",IF(OR(I6="Terminada",I6="Completada"),0,K6-TODAY()))) -> 11 | O6: =IF(A6="","",IF(B6="PROCESO",IF(COUNTIF($C$2:$C$301,A6)=0,"SIN ETAPAS",IF(M6=1,"TERMINADO",IF(N6<0,"ATRASADO",IF(N6<=3,"URGENTE",IF(N6<=7,"PROXIMO","SIN ALERTA"))))),IF(OR(I6="Terminada",I6="Completada"),"TERMINADA",IF(I6="Bloqueada","BLOQUEADA",IF(N6<0,"ATRASADA",IF(N6<=3,"URGENTE",IF(N6<=7,"PROXIMA","SIN ALERTA"))))))) -> SIN ALERTA | P6: =IF(A6="","",IF(OR(I6="Terminada",I6="Completada"),"VERDE",IF(I6="Bloqueada","ROJO",IF(N6<0,"ROJO",IF(N6<=3,"ROJO",IF(N6<=7,"AMARILLO","VERDE")))))) -> VERDE | Q6: =IF(A6="","",IF(OR(B6<>"ETAPA",C6=""),"",1/COUNTIF($C$2:$C$301,C6))) -> 0.125 | R6: Depende de CP-001.3 | S6: Requerimiento | T6: REQ-2026-01 | W6: Enviar a aprobación | X6: 46332 | Y6: Medio
A7: CP-001.5 | B7: ETAPA | C7: CP-001 | D7: Bienes y Servicios | E7: Adquisición de insumos | F7: Publicar / emitir proceso de compra | G7: Compras | H7: Alta | I7: No iniciada | J7: 46335 | K7: 46338 | L7: =IF(A7="","",IF(OR(J7="",K7=""),"",MAX(1,K7-J7+1))) -> 4 | M7: =IF(A7="","",IF(B7="PROCESO",IF(COUNTIF($C$2:$C$301,A7)=0,0,SUMIF($C$2:$C$301,A7,$M$2:$M$301)/COUNTIF($C$2:$C$301,A7)),IF(OR(I7="Terminada",I7="Completada"),1,IF(OR(I7="No iniciada",I7="Cancelada"),0,IF(OR(J7="",K7=""),0,MIN(0.99,MAX(0,(TODAY()-J7+1)/MAX(1,K7-J7+1)))))))) -> 0 | N7: =IF(A7="","",IF(K7="","",IF(OR(I7="Terminada",I7="Completada"),0,K7-TODAY()))) -> 17 | O7: =IF(A7="","",IF(B7="PROCESO",IF(COUNTIF($C$2:$C$301,A7)=0,"SIN ETAPAS",IF(M7=1,"TERMINADO",IF(N7<0,"ATRASADO",IF(N7<=3,"URGENTE",IF(N7<=7,"PROXIMO","SIN ALERTA"))))),IF(OR(I7="Terminada",I7="Completada"),"TERMINADA",IF(I7="Bloqueada","BLOQUEADA",IF(N7<0,"ATRASADA",IF(N7<=3,"URGENTE",IF(N7<=7,"PROXIMA","SIN ALERTA"))))))) -> SIN ALERTA | P7: =IF(A7="","",IF(OR(I7="Terminada",I7="Completada"),"VERDE",IF(I7="Bloqueada","ROJO",IF(N7<0,"ROJO",IF(N7<=3,"ROJO",IF(N7<=7,"AMARILLO","VERDE")))))) -> VERDE | Q7: =IF(A7="","",IF(OR(B7<>"ETAPA",C7=""),"",1/COUNTIF($C$2:$C$301,C7))) -> 0.125 | R7: Depende de aprobación | S7: Publicación | T7: REQ-2026-01 | W7: Evaluación | X7: 46339 | Y7: Medio
A8: CP-001.6 | B8: ETAPA | C8: CP-001 | D8: Bienes y Servicios | E8: Adquisición de insumos | F8: Evaluación y adjudicación | G8: Compras | H8: Alta | I8: No iniciada | J8: 46339 | K8: 46344 | L8: =IF(A8="","",IF(OR(J8="",K8=""),"",MAX(1,K8-J8+1))) -> 6 | M8: =IF(A8="","",IF(B8="PROCESO",IF(COUNTIF($C$2:$C$301,A8)=0,0,SUMIF($C$2:$C$301,A8,$M$2:$M$301)/COUNTIF($C$2:$C$301,A8)),IF(OR(I8="Terminada",I8="Completada"),1,IF(OR(I8="No iniciada",I8="Cancelada"),0,IF(OR(J8="",K8=""),0,MIN(0.99,MAX(0,(TODAY()-J8+1)/MAX(1,K8-J8+1)))))))) -> 0 | N8: =IF(A8="","",IF(K8="","",IF(OR(I8="Terminada",I8="Completada"),0,K8-TODAY()))) -> 23 | O8: =IF(A8="","",IF(B8="PROCESO",IF(COUNTIF($C$2:$C$301,A8)=0,"SIN ETAPAS",IF(M8=1,"TERMINADO",IF(N8<0,"ATRASADO",IF(N8<=3,"URGENTE",IF(N8<=7,"PROXIMO","SIN ALERTA"))))),IF(OR(I8="Terminada",I8="Completada"),"TERMINADA",IF(I8="Bloqueada","BLOQUEADA",IF(N8<0,"ATRASADA",IF(N8<=3,"URGENTE",IF(N8<=7,"PROXIMA","SIN ALERTA"))))))) -> SIN ALERTA | P8: =IF(A8="","",IF(OR(I8="Terminada",I8="Completada"),"VERDE",IF(I8="Bloqueada","ROJO",IF(N8<0,"ROJO",IF(N8<=3,"ROJO",IF(N8<=7,"AMARILLO","VERDE")))))) -> VERDE | Q8: =IF(A8="","",IF(OR(B8<>"ETAPA",C8=""),"",1/COUNTIF($C$2:$C$301,C8))) -> 0.125 | R8: Depende de ofertas válidas | S8: Evaluación | T8: REQ-2026-01 | W8: Emitir OC | X8: 46345 | Y8: Medio
A9: CP-001.7 | B9: ETAPA | C9: CP-001 | D9: Bienes y Servicios | E9: Adquisición de insumos | F9: Emitir y aceptar Orden de Compra | G9: Compras | H9: Alta | I9: No iniciada | J9: 46345 | K9: 46346 | L9: =IF(A9="","",IF(OR(J9="",K9=""),"",MAX(1,K9-J9+1))) -> 2 | M9: =IF(A9="","",IF(B9="PROCESO",IF(COUNTIF($C$2:$C$301,A9)=0,0,SUMIF($C$2:$C$301,A9,$M$2:$M$301)/COUNTIF($C$2:$C$301,A9)),IF(OR(I9="Terminada",I9="Completada"),1,IF(OR(I9="No iniciada",I9="Cancelada"),0,IF(OR(J9="",K9=""),0,MIN(0.99,MAX(0,(TODAY()-J9+1)/MAX(1,K9-J9+1)))))))) -> 0 | N9: =IF(A9="","",IF(K9="","",IF(OR(I9="Terminada",I9="Completada"),0,K9-TODAY()))) -> 25 | O9: =IF(A9="","",IF(B9="PROCESO",IF(COUNTIF($C$2:$C$301,A9)=0,"SIN ETAPAS",IF(M9=1,"TERMINADO",IF(N9<0,"ATRASADO",IF(N9<=3,"URGENTE",IF(N9<=7,"PROXIMO","SIN ALERTA"))))),IF(OR(I9="Terminada",I9="Completada"),"TERMINADA",IF(I9="Bloqueada","BLOQUEADA",IF(N9<0,"ATRASADA",IF(N9<=3,"URGENTE",IF(N9<=7,"PROXIMA","SIN ALERTA"))))))) -> SIN ALERTA | P9: =IF(A9="","",IF(OR(I9="Terminada",I9="Completada"),"VERDE",IF(I9="Bloqueada","ROJO",IF(N9<0,"ROJO",IF(N9<=3,"ROJO",IF(N9<=7,"AMARILLO","VERDE")))))) -> VERDE | Q9: =IF(A9="","",IF(OR(B9<>"ETAPA",C9=""),"",1/COUNTIF($C$2:$C$301,C9))) -> 0.125 | R9: OC debe ser aceptada | S9: OC emitida | T9: REQ-2026-01 | W9: Controlar despacho | X9: 46349 | Y9: Medio
A10: CP-001.8 | B10: ETAPA | C10: CP-001 | D10: Bienes y Servicios | E10: Adquisición de insumos | F10: Despacho, recepción conforme y cierre | G10: Oscar Arias | H10: Crítica | I10: No iniciada | J10: 46349 | K10: 46356 | L10: =IF(A10="","",IF(OR(J10="",K10=""),"",MAX(1,K10-J10+1))) -> 8 | M10: =IF(A10="","",IF(B10="PROCESO",IF(COUNTIF($C$2:$C$301,A10)=0,0,SUMIF($C$2:$C$301,A10,$M$2:$M$301)/COUNTIF($C$2:$C$301,A10)),IF(OR(I10="Terminada",I10="Completada"),1,IF(OR(I10="No iniciada",I10="Cancelada"),0,IF(OR(J10="",K10=""),0,MIN(0.99,MAX(0,(TODAY()-J10+1)/MAX(1,K10-J10+1)))))))) -> 0 | N10: =IF(A10="","",IF(K10="","",IF(OR(I10="Terminada",I10="Completada"),0,K10-TODAY()))) -> 35 | O10: =IF(A10="","",IF(B10="PROCESO",IF(COUNTIF($C$2:$C$301,A10)=0,"SIN ETAPAS",IF(M10=1,"TERMINADO",IF(N10<0,"ATRASADO",IF(N10<=3,"URGENTE",IF(N10<=7,"PROXIMO","SIN ALERTA"))))),IF(OR(I10="Terminada",I10="Completada"),"TERMINADA",IF(I10="Bloqueada","BLOQUEADA",IF(N10<0,"ATRASADA",IF(N10<=3,"URGENTE",IF(N10<=7,"PROXIMA","SIN ALERTA"))))))) -> SIN ALERTA | P10: =IF(A10="","",IF(OR(I10="Terminada",I10="Completada"),"VERDE",IF(I10="Bloqueada","ROJO",IF(N10<0,"ROJO",IF(N10<=3,"ROJO",IF(N10<=7,"AMARILLO","VERDE")))))) -> VERDE | Q10: =IF(A10="","",IF(OR(B10<>"ETAPA",C10=""),"",1/COUNTIF($C$2:$C$301,C10))) -> 0.125 | R10: Cierre contra recepción conforme | S10: Recepción conforme | T10: REQ-2026-01 | W10: Cerrar proceso | X10: 46356 | Y10: Alto
A11: ADM-001 | B11: ETAPA | D11: Administración | E11: Gestión Administrativa | F11: Elaborar informe administrativo mensual | G11: Oscar Arias | H11: Media | I11: En curso | J11: 46321 | K11: 46325 | L11: =IF(A11="","",IF(OR(J11="",K11=""),"",MAX(1,K11-J11+1))) -> 5 | M11: =IF(A11="","",IF(B11="PROCESO",IF(COUNTIF($C$2:$C$301,A11)=0,0,SUMIF($C$2:$C$301,A11,$M$2:$M$301)/COUNTIF($C$2:$C$301,A11)),IF(OR(I11="Terminada",I11="Completada"),1,IF(OR(I11="No iniciada",I11="Cancelada"),0,IF(OR(J11="",K11=""),0,MIN(0.99,MAX(0,(TODAY()-J11+1)/MAX(1,K11-J11+1)))))))) -> 0.2 | N11: =IF(A11="","",IF(K11="","",IF(OR(I11="Terminada",I11="Completada"),0,K11-TODAY()))) -> 4 | O11: =IF(A11="","",IF(B11="PROCESO",IF(COUNTIF($C$2:$C$301,A11)=0,"SIN ETAPAS",IF(M11=1,"TERMINADO",IF(N11<0,"ATRASADO",IF(N11<=3,"URGENTE",IF(N11<=7,"PROXIMO","SIN ALERTA"))))),IF(OR(I11="Terminada",I11="Completada"),"TERMINADA",IF(I11="Bloqueada","BLOQUEADA",IF(N11<0,"ATRASADA",IF(N11<=3,"URGENTE",IF(N11<=7,"PROXIMA","SIN ALERTA"))))))) -> PROXIMA | P11: =IF(A11="","",IF(OR(I11="Terminada",I11="Completada"),"VERDE",IF(I11="Bloqueada","ROJO",IF(N11<0,"ROJO",IF(N11<=3,"ROJO",IF(N11<=7,"AMARILLO","VERDE")))))) -> AMARILLO | Q11: =IF(A11="","",IF(OR(B11<>"ETAPA",C11=""),"",1/COUNTIF($C$2:$C$301,C11))) | R11: Tarea única: el avance se calcula por el tiempo transcurrido entre inicio y término. | W11: Enviar informe | X11: 46325 | Y11: Bajo
L12: =IF(A12="","",IF(OR(J12="",K12=""),"",MAX(1,K12-J12+1))) | M12: =IF(A12="","",IF(B12="PROCESO",IF(COUNTIF($C$2:$C$301,A12)=0,0,SUMIF($C$2:$C$301,A12,$M$2:$M$301)/COUNTIF($C$2:$C$301,A12)),IF(OR(I12="Terminada",I12="Completada"),1,IF(OR(I12="No iniciada",I12="Cancelada"),0,IF(OR(J12="",K12=""),0,MIN(0.99,MAX(0,(TODAY()-J12+1)/MAX(1,K12-J12+1)))))))) | N12: =IF(A12="","",IF(K12="","",IF(OR(I12="Terminada",I12="Completada"),0,K12-TODAY()))) | O12: =IF(A12="","",IF(B12="PROCESO",IF(COUNTIF($C$2:$C$301,A12)=0,"SIN ETAPAS",IF(M12=1,"TERMINADO",IF(N12<0,"ATRASADO",IF(N12<=3,"URGENTE",IF(N12<=7,"PROXIMO","SIN ALERTA"))))),IF(OR(I12="Terminada",I12="Completada"),"TERMINADA",IF(I12="Bloqueada","BLOQUEADA",IF(N12<0,"ATRASADA",IF(N12<=3,"URGENTE",IF(N12<=7,"PROXIMA","SIN ALERTA"))))))) | P12: =IF(A12="","",IF(OR(I12="Terminada",I12="Completada"),"VERDE",IF(I12="Bloqueada","ROJO",IF(N12<0,"ROJO",IF(N12<=3,"ROJO",IF(N12<=7,"AMARILLO","VERDE")))))) | Q12: =IF(A12="","",IF(OR(B12<>"ETAPA",C12=""),"",1/COUNTIF($C$2:$C$301,C12)))
L13: =IF(A13="","",IF(OR(J13="",K13=""),"",MAX(1,K13-J13+1))) | M13: =IF(A13="","",IF(B13="PROCESO",IF(COUNTIF($C$2:$C$301,A13)=0,0,SUMIF($C$2:$C$301,A13,$M$2:$M$301)/COUNTIF($C$2:$C$301,A13)),IF(OR(I13="Terminada",I13="Completada"),1,IF(OR(I13="No iniciada",I13="Cancelada"),0,IF(OR(J13="",K13=""),0,MIN(0.99,MAX(0,(TODAY()-J13+1)/MAX(1,K13-J13+1)))))))) | N13: =IF(A13="","",IF(K13="","",IF(OR(I13="Terminada",I13="Completada"),0,K13-TODAY()))) | O13: =IF(A13="","",IF(B13="PROCESO",IF(COUNTIF($C$2:$C$301,A13)=0,"SIN ETAPAS",IF(M13=1,"TERMINADO",IF(N13<0,"ATRASADO",IF(N13<=3,"URGENTE",IF(N13<=7,"PROXIMO","SIN ALERTA"))))),IF(OR(I13="Terminada",I13="Completada"),"TERMINADA",IF(I13="Bloqueada","BLOQUEADA",IF(N13<0,"ATRASADA",IF(N13<=3,"URGENTE",IF(N13<=7,"PROXIMA","SIN ALERTA"))))))) | P13: =IF(A13="","",IF(OR(I13="Terminada",I13="Completada"),"VERDE",IF(I13="Bloqueada","ROJO",IF(N13<0,"ROJO",IF(N13<=3,"ROJO",IF(N13<=7,"AMARILLO","VERDE")))))) | Q13: =IF(A13="","",IF(OR(B13<>"ETAPA",C13=""),"",1/COUNTIF($C$2:$C$301,C13)))
L14: =IF(A14="","",IF(OR(J14="",K14=""),"",MAX(1,K14-J14+1))) | M14: =IF(A14="","",IF(B14="PROCESO",IF(COUNTIF($C$2:$C$301,A14)=0,0,SUMIF($C$2:$C$301,A14,$M$2:$M$301)/COUNTIF($C$2:$C$301,A14)),IF(OR(I14="Terminada",I14="Completada"),1,IF(OR(I14="No iniciada",I14="Cancelada"),0,IF(OR(J14="",K14=""),0,MIN(0.99,MAX(0,(TODAY()-J14+1)/MAX(1,K14-J14+1)))))))) | N14: =IF(A14="","",IF(K14="","",IF(OR(I14="Terminada",I14="Completada"),0,K14-TODAY()))) | O14: =IF(A14="","",IF(B14="PROCESO",IF(COUNTIF($C$2:$C$301,A14)=0,"SIN ETAPAS",IF(M14=1,"TERMINADO",IF(N14<0,"ATRASADO",IF(N14<=3,"URGENTE",IF(N14<=7,"PROXIMO","SIN ALERTA"))))),IF(OR(I14="Terminada",I14="Completada"),"TERMINADA",IF(I14="Bloqueada","BLOQUEADA",IF(N14<0,"ATRASADA",IF(N14<=3,"URGENTE",IF(N14<=7,"PROXIMA","SIN ALERTA"))))))) | P14: =IF(A14="","",IF(OR(I14="Terminada",I14="Completada"),"VERDE",IF(I14="Bloqueada","ROJO",IF(N14<0,"ROJO",IF(N14<=3,"ROJO",IF(N14<=7,"AMARILLO","VERDE")))))) | Q14: =IF(A14="","",IF(OR(B14<>"ETAPA",C14=""),"",1/COUNTIF($C$2:$C$301,C14)))
L15: =IF(A15="","",IF(OR(J15="",K15=""),"",MAX(1,K15-J15+1))) | M15: =IF(A15="","",IF(B15="PROCESO",IF(COUNTIF($C$2:$C$301,A15)=0,0,SUMIF($C$2:$C$301,A15,$M$2:$M$301)/COUNTIF($C$2:$C$301,A15)),IF(OR(I15="Terminada",I15="Completada"),1,IF(OR(I15="No iniciada",I15="Cancelada"),0,IF(OR(J15="",K15=""),0,MIN(0.99,MAX(0,(TODAY()-J15+1)/MAX(1,K15-J15+1)))))))) | N15: =IF(A15="","",IF(K15="","",IF(OR(I15="Terminada",I15="Completada"),0,K15-TODAY()))) | O15: =IF(A15="","",IF(B15="PROCESO",IF(COUNTIF($C$2:$C$301,A15)=0,"SIN ETAPAS",IF(M15=1,"TERMINADO",IF(N15<0,"ATRASADO",IF(N15<=3,"URGENTE",IF(N15<=7,"PROXIMO","SIN ALERTA"))))),IF(OR(I15="Terminada",I15="Completada"),"TERMINADA",IF(I15="Bloqueada","BLOQUEADA",IF(N15<0,"ATRASADA",IF(N15<=3,"URGENTE",IF(N15<=7,"PROXIMA","SIN ALERTA"))))))) | P15: =IF(A15="","",IF(OR(I15="Terminada",I15="Completada"),"VERDE",IF(I15="Bloqueada","ROJO",IF(N15<0,"ROJO",IF(N15<=3,"ROJO",IF(N15<=7,"AMARILLO","VERDE")))))) | Q15: =IF(A15="","",IF(OR(B15<>"ETAPA",C15=""),"",1/COUNTIF($C$2:$C$301,C15)))
L16: =IF(A16="","",IF(OR(J16="",K16=""),"",MAX(1,K16-J16+1))) | M16: =IF(A16="","",IF(B16="PROCESO",IF(COUNTIF($C$2:$C$301,A16)=0,0,SUMIF($C$2:$C$301,A16,$M$2:$M$301)/COUNTIF($C$2:$C$301,A16)),IF(OR(I16="Terminada",I16="Completada"),1,IF(OR(I16="No iniciada",I16="Cancelada"),0,IF(OR(J16="",K16=""),0,MIN(0.99,MAX(0,(TODAY()-J16+1)/MAX(1,K16-J16+1)))))))) | N16: =IF(A16="","",IF(K16="","",IF(OR(I16="Terminada",I16="Completada"),0,K16-TODAY()))) | O16: =IF(A16="","",IF(B16="PROCESO",IF(COUNTIF($C$2:$C$301,A16)=0,"SIN ETAPAS",IF(M16=1,"TERMINADO",IF(N16<0,"ATRASADO",IF(N16<=3,"URGENTE",IF(N16<=7,"PROXIMO","SIN ALERTA"))))),IF(OR(I16="Terminada",I16="Completada"),"TERMINADA",IF(I16="Bloqueada","BLOQUEADA",IF(N16<0,"ATRASADA",IF(N16<=3,"URGENTE",IF(N16<=7,"PROXIMA","SIN ALERTA"))))))) | P16: =IF(A16="","",IF(OR(I16="Terminada",I16="Completada"),"VERDE",IF(I16="Bloqueada","ROJO",IF(N16<0,"ROJO",IF(N16<=3,"ROJO",IF(N16<=7,"AMARILLO","VERDE")))))) | Q16: =IF(A16="","",IF(OR(B16<>"ETAPA",C16=""),"",1/COUNTIF($C$2:$C$301,C16)))
L17: =IF(A17="","",IF(OR(J17="",K17=""),"",MAX(1,K17-J17+1))) | M17: =IF(A17="","",IF(B17="PROCESO",IF(COUNTIF($C$2:$C$301,A17)=0,0,SUMIF($C$2:$C$301,A17,$M$2:$M$301)/COUNTIF($C$2:$C$301,A17)),IF(OR(I17="Terminada",I17="Completada"),1,IF(OR(I17="No iniciada",I17="Cancelada"),0,IF(OR(J17="",K17=""),0,MIN(0.99,MAX(0,(TODAY()-J17+1)/MAX(1,K17-J17+1)))))))) | N17: =IF(A17="","",IF(K17="","",IF(OR(I17="Terminada",I17="Completada"),0,K17-TODAY()))) | O17: =IF(A17="","",IF(B17="PROCESO",IF(COUNTIF($C$2:$C$301,A17)=0,"SIN ETAPAS",IF(M17=1,"TERMINADO",IF(N17<0,"ATRASADO",IF(N17<=3,"URGENTE",IF(N17<=7,"PROXIMO","SIN ALERTA"))))),IF(OR(I17="Terminada",I17="Completada"),"TERMINADA",IF(I17="Bloqueada","BLOQUEADA",IF(N17<0,"ATRASADA",IF(N17<=3,"URGENTE",IF(N17<=7,"PROXIMA","SIN ALERTA"))))))) | P17: =IF(A17="","",IF(OR(I17="Terminada",I17="Completada"),"VERDE",IF(I17="Bloqueada","ROJO",IF(N17<0,"ROJO",IF(N17<=3,"ROJO",IF(N17<=7,"AMARILLO","VERDE")))))) | Q17: =IF(A17="","",IF(OR(B17<>"ETAPA",C17=""),"",1/COUNTIF($C$2:$C$301,C17)))
L18: =IF(A18="","",IF(OR(J18="",K18=""),"",MAX(1,K18-J18+1))) | M18: =IF(A18="","",IF(B18="PROCESO",IF(COUNTIF($C$2:$C$301,A18)=0,0,SUMIF($C$2:$C$301,A18,$M$2:$M$301)/COUNTIF($C$2:$C$301,A18)),IF(OR(I18="Terminada",I18="Completada"),1,IF(OR(I18="No iniciada",I18="Cancelada"),0,IF(OR(J18="",K18=""),0,MIN(0.99,MAX(0,(TODAY()-J18+1)/MAX(1,K18-J18+1)))))))) | N18: =IF(A18="","",IF(K18="","",IF(OR(I18="Terminada",I18="Completada"),0,K18-TODAY()))) | O18: =IF(A18="","",IF(B18="PROCESO",IF(COUNTIF($C$2:$C$301,A18)=0,"SIN ETAPAS",IF(M18=1,"TERMINADO",IF(N18<0,"ATRASADO",IF(N18<=3,"URGENTE",IF(N18<=7,"PROXIMO","SIN ALERTA"))))),IF(OR(I18="Terminada",I18="Completada"),"TERMINADA",IF(I18="Bloqueada","BLOQUEADA",IF(N18<0,"ATRASADA",IF(N18<=3,"URGENTE",IF(N18<=7,"PROXIMA","SIN ALERTA"))))))) | P18: =IF(A18="","",IF(OR(I18="Terminada",I18="Completada"),"VERDE",IF(I18="Bloqueada","ROJO",IF(N18<0,"ROJO",IF(N18<=3,"ROJO",IF(N18<=7,"AMARILLO","VERDE")))))) | Q18: =IF(A18="","",IF(OR(B18<>"ETAPA",C18=""),"",1/COUNTIF($C$2:$C$301,C18)))
L19: =IF(A19="","",IF(OR(J19="",K19=""),"",MAX(1,K19-J19+1))) | M19: =IF(A19="","",IF(B19="PROCESO",IF(COUNTIF($C$2:$C$301,A19)=0,0,SUMIF($C$2:$C$301,A19,$M$2:$M$301)/COUNTIF($C$2:$C$301,A19)),IF(OR(I19="Terminada",I19="Completada"),1,IF(OR(I19="No iniciada",I19="Cancelada"),0,IF(OR(J19="",K19=""),0,MIN(0.99,MAX(0,(TODAY()-J19+1)/MAX(1,K19-J19+1)))))))) | N19: =IF(A19="","",IF(K19="","",IF(OR(I19="Terminada",I19="Completada"),0,K19-TODAY()))) | O19: =IF(A19="","",IF(B19="PROCESO",IF(COUNTIF($C$2:$C$301,A19)=0,"SIN ETAPAS",IF(M19=1,"TERMINADO",IF(N19<0,"ATRASADO",IF(N19<=3,"URGENTE",IF(N19<=7,"PROXIMO","SIN ALERTA"))))),IF(OR(I19="Terminada",I19="Completada"),"TERMINADA",IF(I19="Bloqueada","BLOQUEADA",IF(N19<0,"ATRASADA",IF(N19<=3,"URGENTE",IF(N19<=7,"PROXIMA","SIN ALERTA"))))))) | P19: =IF(A19="","",IF(OR(I19="Terminada",I19="Completada"),"VERDE",IF(I19="Bloqueada","ROJO",IF(N19<0,"ROJO",IF(N19<=3,"ROJO",IF(N19<=7,"AMARILLO","VERDE")))))) | Q19: =IF(A19="","",IF(OR(B19<>"ETAPA",C19=""),"",1/COUNTIF($C$2:$C$301,C19)))
L20: =IF(A20="","",IF(OR(J20="",K20=""),"",MAX(1,K20-J20+1))) | M20: =IF(A20="","",IF(B20="PROCESO",IF(COUNTIF($C$2:$C$301,A20)=0,0,SUMIF($C$2:$C$301,A20,$M$2:$M$301)/COUNTIF($C$2:$C$301,A20)),IF(OR(I20="Terminada",I20="Completada"),1,IF(OR(I20="No iniciada",I20="Cancelada"),0,IF(OR(J20="",K20=""),0,MIN(0.99,MAX(0,(TODAY()-J20+1)/MAX(1,K20-J20+1)))))))) | N20: =IF(A20="","",IF(K20="","",IF(OR(I20="Terminada",I20="Completada"),0,K20-TODAY()))) | O20: =IF(A20="","",IF(B20="PROCESO",IF(COUNTIF($C$2:$C$301,A20)=0,"SIN ETAPAS",IF(M20=1,"TERMINADO",IF(N20<0,"ATRASADO",IF(N20<=3,"URGENTE",IF(N20<=7,"PROXIMO","SIN ALERTA"))))),IF(OR(I20="Terminada",I20="Completada"),"TERMINADA",IF(I20="Bloqueada","BLOQUEADA",IF(N20<0,"ATRASADA",IF(N20<=3,"URGENTE",IF(N20<=7,"PROXIMA","SIN ALERTA"))))))) | P20: =IF(A20="","",IF(OR(I20="Terminada",I20="Completada"),"VERDE",IF(I20="Bloqueada","ROJO",IF(N20<0,"ROJO",IF(N20<=3,"ROJO",IF(N20<=7,"AMARILLO","VERDE")))))) | Q20: =IF(A20="","",IF(OR(B20<>"ETAPA",C20=""),"",1/COUNTIF($C$2:$C$301,C20)))
L21: =IF(A21="","",IF(OR(J21="",K21=""),"",MAX(1,K21-J21+1))) | M21: =IF(A21="","",IF(B21="PROCESO",IF(COUNTIF($C$2:$C$301,A21)=0,0,SUMIF($C$2:$C$301,A21,$M$2:$M$301)/COUNTIF($C$2:$C$301,A21)),IF(OR(I21="Terminada",I21="Completada"),1,IF(OR(I21="No iniciada",I21="Cancelada"),0,IF(OR(J21="",K21=""),0,MIN(0.99,MAX(0,(TODAY()-J21+1)/MAX(1,K21-J21+1)))))))) | N21: =IF(A21="","",IF(K21="","",IF(OR(I21="Terminada",I21="Completada"),0,K21-TODAY()))) | O21: =IF(A21="","",IF(B21="PROCESO",IF(COUNTIF($C$2:$C$301,A21)=0,"SIN ETAPAS",IF(M21=1,"TERMINADO",IF(N21<0,"ATRASADO",IF(N21<=3,"URGENTE",IF(N21<=7,"PROXIMO","SIN ALERTA"))))),IF(OR(I21="Terminada",I21="Completada"),"TERMINADA",IF(I21="Bloqueada","BLOQUEADA",IF(N21<0,"ATRASADA",IF(N21<=3,"URGENTE",IF(N21<=7,"PROXIMA","SIN ALERTA"))))))) | P21: =IF(A21="","",IF(OR(I21="Terminada",I21="Completada"),"VERDE",IF(I21="Bloqueada","ROJO",IF(N21<0,"ROJO",IF(N21<=3,"ROJO",IF(N21<=7,"AMARILLO","VERDE")))))) | Q21: =IF(A21="","",IF(OR(B21<>"ETAPA",C21=""),"",1/COUNTIF($C$2:$C$301,C21)))
L22: =IF(A22="","",IF(OR(J22="",K22=""),"",MAX(1,K22-J22+1))) | M22: =IF(A22="","",IF(B22="PROCESO",IF(COUNTIF($C$2:$C$301,A22)=0,0,SUMIF($C$2:$C$301,A22,$M$2:$M$301)/COUNTIF($C$2:$C$301,A22)),IF(OR(I22="Terminada",I22="Completada"),1,IF(OR(I22="No iniciada",I22="Cancelada"),0,IF(OR(J22="",K22=""),0,MIN(0.99,MAX(0,(TODAY()-J22+1)/MAX(1,K22-J22+1)))))))) | N22: =IF(A22="","",IF(K22="","",IF(OR(I22="Terminada",I22="Completada"),0,K22-TODAY()))) | O22: =IF(A22="","",IF(B22="PROCESO",IF(COUNTIF($C$2:$C$301,A22)=0,"SIN ETAPAS",IF(M22=1,"TERMINADO",IF(N22<0,"ATRASADO",IF(N22<=3,"URGENTE",IF(N22<=7,"PROXIMO","SIN ALERTA"))))),IF(OR(I22="Terminada",I22="Completada"),"TERMINADA",IF(I22="Bloqueada","BLOQUEADA",IF(N22<0,"ATRASADA",IF(N22<=3,"URGENTE",IF(N22<=7,"PROXIMA","SIN ALERTA"))))))) | P22: =IF(A22="","",IF(OR(I22="Terminada",I22="Completada"),"VERDE",IF(I22="Bloqueada","ROJO",IF(N22<0,"ROJO",IF(N22<=3,"ROJO",IF(N22<=7,"AMARILLO","VERDE")))))) | Q22: =IF(A22="","",IF(OR(B22<>"ETAPA",C22=""),"",1/COUNTIF($C$2:$C$301,C22)))
L23: =IF(A23="","",IF(OR(J23="",K23=""),"",MAX(1,K23-J23+1))) | M23: =IF(A23="","",IF(B23="PROCESO",IF(COUNTIF($C$2:$C$301,A23)=0,0,SUMIF($C$2:$C$301,A23,$M$2:$M$301)/COUNTIF($C$2:$C$301,A23)),IF(OR(I23="Terminada",I23="Completada"),1,IF(OR(I23="No iniciada",I23="Cancelada"),0,IF(OR(J23="",K23=""),0,MIN(0.99,MAX(0,(TODAY()-J23+1)/MAX(1,K23-J23+1)))))))) | N23: =IF(A23="","",IF(K23="","",IF(OR(I23="Terminada",I23="Completada"),0,K23-TODAY()))) | O23: =IF(A23="","",IF(B23="PROCESO",IF(COUNTIF($C$2:$C$301,A23)=0,"SIN ETAPAS",IF(M23=1,"TERMINADO",IF(N23<0,"ATRASADO",IF(N23<=3,"URGENTE",IF(N23<=7,"PROXIMO","SIN ALERTA"))))),IF(OR(I23="Terminada",I23="Completada"),"TERMINADA",IF(I23="Bloqueada","BLOQUEADA",IF(N23<0,"ATRASADA",IF(N23<=3,"URGENTE",IF(N23<=7,"PROXIMA","SIN ALERTA"))))))) | P23: =IF(A23="","",IF(OR(I23="Terminada",I23="Completada"),"VERDE",IF(I23="Bloqueada","ROJO",IF(N23<0,"ROJO",IF(N23<=3,"ROJO",IF(N23<=7,"AMARILLO","VERDE")))))) | Q23: =IF(A23="","",IF(OR(B23<>"ETAPA",C23=""),"",1/COUNTIF($C$2:$C$301,C23)))
... L301: =IF(A301="","",IF(OR(J301="",K301=""),"",MAX(1,K301-J301+1))) | M301: =IF(A301="","",IF(B301="PROCESO",IF(COUNTIF($C$2:$C$301,A301)=0,0,SUMIF($C$2:$C$301,A301,$M$2:$M$301)/COUNTIF($C$2:$C$301,A301)),IF(OR(I301="Terminada",I301="Completada"),1,IF(OR(I301="No iniciada",I301="Cancelada"),0,IF(OR(J301="",K301=""),0,MIN(0.99,MAX(0,(TODAY()-J301+1)/MAX(1,K301-J301+1)))))))) | N301: =IF(A301="","",IF(K301="","",IF(OR(I301="Terminada",I301="Completada"),0,K301-TODAY()))) | O301: =IF(A301="","",IF(B301="PROCESO",IF(COUNTIF($C$2:$C$301,A301)=0,"SIN ETAPAS",IF(M301=1,"TERMINADO",IF(N301<0,"ATRASADO",IF(N301<=3,"URGENTE",IF(N301<=7,"PROXIMO","SIN ALERTA"))))),IF(OR(I301="Terminada",I301="Completada"),"TERMINADA",IF(I301="Bloqueada","BLOQUEADA",IF(N301<0,"ATRASADA",IF(N301<=3,"URGENTE",IF(N301<=7,"PROXIMA","SIN ALERTA"))))))) | P301: =IF(A301="","",IF(OR(I301="Terminada",I301="Completada"),"VERDE",IF(I301="Bloqueada","ROJO",IF(N301<0,"ROJO",IF(N301<=3,"ROJO",IF(N301<=7,"AMARILLO","VERDE")))))) | Q301: =IF(A301="","",IF(OR(B301<>"ETAPA",C301=""),"",1/COUNTIF($C$2:$C$301,C301)))

Sheet Carta Gantt
A1: CARTA GANTT DINÁMICA
A2: ID | B2: Etapa / Tarea | C2: Responsable | D2: Inicio | E2: Término | F2: % Avance | G2: 46321 | H2: 46328 | I2: 46335 | J2: 46342 | K2: 46349 | L2: 46356 | M2: 46363 | N2: 46370 | O2: 46377 | P2: 46384 | Q2: 46391 | R2: 46398 | S2: 46405 | T2: 46412 | U2: 46419 | V2: 46426 | W2: 46433 | X2: 46440 | Y2: 46447 | Z2: 46454 | AA2: 46461 | AB2: 46468 | AC2: 46475 | AD2: 46482 | AE2: 46489 | AF2: 46496
A3: ='Plan de Tareas'!A2 -> CP-001 | B3: ='Plan de Tareas'!F2 -> Proceso completo de compra | C3: ='Plan de Tareas'!G2 -> Oscar Arias | D3: ='Plan de Tareas'!J2 -> 46321 | E3: ='Plan de Tareas'!K2 -> 46356 | F3: ='Plan de Tareas'!M2 -> 0.25
A4: ='Plan de Tareas'!A3 -> CP-001.1 | B4: ='Plan de Tareas'!F3 -> Revisar necesidad y especificaciones | C4: ='Plan de Tareas'!G3 -> Oscar Arias | D4: ='Plan de Tareas'!J3 -> 46321 | E4: ='Plan de Tareas'!K3 -> 46322 | F4: ='Plan de Tareas'!M3 -> 1
A5: ='Plan de Tareas'!A4 -> CP-001.2 | B5: ='Plan de Tareas'!F4 -> Ver precios y referencias de mercado | C5: ='Plan de Tareas'!G4 -> Oscar Arias | D5: ='Plan de Tareas'!J4 -> 46323 | E5: ='Plan de Tareas'!K4 -> 46324 | F5: ='Plan de Tareas'!M4 -> 1
A6: ='Plan de Tareas'!A5 -> CP-001.3 | B6: ='Plan de Tareas'!F5 -> Revisar Convenio Marco / Compra Ágil | C6: ='Plan de Tareas'!G5 -> Oscar Arias | D6: ='Plan de Tareas'!J5 -> 46325 | E6: ='Plan de Tareas'!K5 -> 46329 | F6: ='Plan de Tareas'!M5 -> 0
A7: ='Plan de Tareas'!A6 -> CP-001.4 | B7: ='Plan de Tareas'!F6 -> Preparar y aprobar requerimiento | C7: ='Plan de Tareas'!G6 -> Oscar Arias | D7: ='Plan de Tareas'!J6 -> 46330 | E7: ='Plan de Tareas'!K6 -> 46332 | F7: ='Plan de Tareas'!M6 -> 0
A8: ='Plan de Tareas'!A7 -> CP-001.5 | B8: ='Plan de Tareas'!F7 -> Publicar / emitir proceso de compra | C8: ='Plan de Tareas'!G7 -> Compras | D8: ='Plan de Tareas'!J7 -> 46335 | E8: ='Plan de Tareas'!K7 -> 46338 | F8: ='Plan de Tareas'!M7 -> 0
A9: ='Plan de Tareas'!A8 -> CP-001.6 | B9: ='Plan de Tareas'!F8 -> Evaluación y adjudicación | C9: ='Plan de Tareas'!G8 -> Compras | D9: ='Plan de Tareas'!J8 -> 46339 | E9: ='Plan de Tareas'!K8 -> 46344 | F9: ='Plan de Tareas'!M8 -> 0
A10: ='Plan de Tareas'!A9 -> CP-001.7 | B10: ='Plan de Tareas'!F9 -> Emitir y aceptar Orden de Compra | C10: ='Plan de Tareas'!G9 -> Compras | D10: ='Plan de Tareas'!J9 -> 46345 | E10: ='Plan de Tareas'!K9 -> 46346 | F10: ='Plan de Tareas'!M9 -> 0
A11: ='Plan de Tareas'!A10 -> CP-001.8 | B11: ='Plan de Tareas'!F10 -> Despacho, recepción conforme y cierre | C11: ='Plan de Tareas'!G10 -> Oscar Arias | D11: ='Plan de Tareas'!J10 -> 46349 | E11: ='Plan de Tareas'!K10 -> 46356 | F11: ='Plan de Tareas'!M10 -> 0
A12: ='Plan de Tareas'!A11 -> ADM-001 | B12: ='Plan de Tareas'!F11 -> Elaborar informe administrativo mensual | C12: ='Plan de Tareas'!G11 -> Oscar Arias | D12: ='Plan de Tareas'!J11 -> 46321 | E12: ='Plan de Tareas'!K11 -> 46325 | F12: ='Plan de Tareas'!M11 -> 0.2
A13: ='Plan de Tareas'!A12 -> 0 | B13: ='Plan de Tareas'!F12 -> 0 | C13: ='Plan de Tareas'!G12 -> 0 | D13: ='Plan de Tareas'!J12 -> 0 | E13: ='Plan de Tareas'!K12 -> 0 | F13: ='Plan de Tareas'!M12
A14: ='Plan de Tareas'!A13 -> 0 | B14: ='Plan de Tareas'!F13 -> 0 | C14: ='Plan de Tareas'!G13 -> 0 | D14: ='Plan de Tareas'!J13 -> 0 | E14: ='Plan de Tareas'!K13 -> 0 | F14: ='Plan de Tareas'!M13
... A102: ='Plan de Tareas'!A101 -> 0 | B102: ='Plan de Tareas'!F101 -> 0 | C102: ='Plan de Tareas'!G101 -> 0 | D102: ='Plan de Tareas'!J101 -> 0 | E102: ='Plan de Tareas'!K101 -> 0 | F102: ='Plan de Tareas'!M101

Sheet Configuracion
A1: ESTADOS | B1: PRIORIDADES | C1: TIPOS | D1: AREAS | E1: RESPONSABLES | F1: HITOS COMPRA | G1: RIESGO | H1: DEPENDENCIA | I1: NIVEL | J1: MODO DE AVANCE
A2: No iniciada | B2: Crítica | C2: Administrativa | D2: Bienes y Servicios | E2: Oscar Arias | F2: Requerimiento | G2: Bajo | H2: Sin dependencia | I2: PROCESO | J2: Automático por etapas
A3: En curso | B3: Alta | C3: Compra Pública | D3: Finanzas | E3: Jefatura UA | F3: Cotización | G3: Medio | H3: Depende de otra tarea | I3: ETAPA | J3: Automático por fechas/estado
A4: En espera | B4: Media | C4: Inventario | D4: RR.HH. | E4: Compras | F4: Convenio Marco | G4: Alto | H4: Depende de proveedor
A5: Bloqueada | B5: Baja | C5: Bodega | D5: Prevención de Riesgos | E5: Bodega | F5: Compra Ágil | G5: Crítico | H5: Depende de jefatura
A6: Terminada | B6: Sin prioridad | C6: Prevención | D6: Administración | E6: Inventario | F6: Bases/TDR | G6: Sin evaluar | H6: Depende de presupuesto
A7: Cancelada | C7: Mantención | D7: Frontera | E7: Prevención | F7: Publicación | H7: Depende de recepción
A8: Completada | C8: Vehículos | D8: Inventario | E8: Finanzas | F8: Evaluación | H8: Depende de tercero
A9: Pendiente de tercero | C9: Resoluciones | D9: Bodega | E9: RR.HH. | F9: Adjudicación
A10: En revisión | C10: RR.HH. | D10: Vehículos | E10: TI | F10: OC emitida
A11: Observada | C11: Finanzas | D11: TI | E11: Proveedor | F11: OC aceptada
A12: Suspendida | C12: Infraestructura | D12: Dirección Regional | E12: Jefatura Regional | F12: Despacho
C13: TI / Sistemas | D13: Otra | E13: Otro | F13: Recepción conforme
C14: Capacitación | F14: Pago
C15: Terreno | F15: Cierre
C16: Otro

Sheet Guia de Uso
A1: GUÍA RÁPIDA – SISTEMA DE PLANIFICACIÓN
A4: Paso | B4: Funcionamiento
A5: 1 | B5: Mantenga un ID principal de proceso, por ejemplo CP-001.
A6: 2 | B6: Las etapas relacionadas usan CP-001.1, CP-001.2, CP-001.3, etc. y deben indicar CP-001 en ID Proceso Padre.
A7: 3 | B7: % Participación automática se calcula solo: 2 etapas = 50% c/u; 3 = 33,33%; 4 = 25%; 5 = 20%; 10 = 10%.
A8: 4 | B8: Si agrega una nueva etapa al mismo proceso, Excel redistribuye automáticamente el porcentaje entre todas.
A9: 5 | B9: % Avance Automático del proceso es el promedio de todas sus etapas relacionadas.
A10: 6 | B10: Terminada o Completada = 100%. En curso avanza por fecha, pero nunca supera 99% hasta finalizar.
A11: 7 | B11: Duración (días) es un número de días entre inicio y término planificado; ya no se muestra como porcentaje.
A12: 8 | B12: Días restantes: positivo = días que faltan; negativo = días de atraso; al terminar = 0.
A13: 9 | B13: Semáforo: VERDE normal/terminada; AMARILLO vence dentro de 7 días; ROJO vence dentro de 3 días, está atrasada o bloqueada.
A14: 10 | B14: Alerta y semáforo se calculan automáticamente; no deben editarse manualmente.
A15: 11 | B15: Para una tarea única sin proceso padre, deje ID Proceso Padre vacío. El avance se calcula por fechas y estado, sin necesidad de asignar porcentaje.

Sheet Procedimiento de Llenado
A1: PROCEDIMIENTO DE LLENADO Y CONTROL – PLANIFICADOR GANTT
A3: Guía operativa para registrar procesos, etapas, fechas, responsables, compras públicas y utilizar correctamente los cálculos automáticos.
A5: 1. OBJETIVO Y REGLAS GENERALES
A6: Objetivo | B6: Registrar y controlar en una sola planilla procesos administrativos, compras públicas y otras gestiones, visualizando avance, plazos, alertas y Carta Gantt.
A7: Regla 1 | B7: Cada trabajo general debe tener un ID único. Ejemplo: CP-001 para una compra pública o ADM-001 para una tarea administrativa.
A8: Regla 2 | B8: Si el trabajo contiene varias actividades, cree una fila PROCESO y luego filas ETAPA asociadas mediante la columna ID Proceso Padre.
A9: Regla 3 | B9: No modificar manualmente las columnas automáticas: Duración, % Avance Automático, Días restantes, Alerta, Semáforo y % Participación automática.
A10: Regla 4 | B10: Las fechas, estados y relaciones entre proceso/etapas deben mantenerse actualizadas; de ellas dependen los indicadores del Dashboard y la Carta Gantt.
A12: 2. ORDEN RECOMENDADO DE LLENADO
A13: Paso 1 | B13: Definir si el registro corresponde a un PROCESO completo o a una ETAPA/tarea.
A14: Paso 2 | B14: Asignar ID. Para un proceso: CP-001. Para sus etapas: CP-001.1, CP-001.2, CP-001.3, etc.
A15: Paso 3 | B15: En cada ETAPA relacionada, escribir el ID principal en ID Proceso Padre. Ej.: todas las etapas CP-001.x deben indicar CP-001.
A16: Paso 4 | B16: Seleccionar Área, Responsable, Prioridad y Estado mediante las listas desplegables.
A17: Paso 5 | B17: Ingresar Fecha inicio y Fecha término planificada. La duración y los días restantes se calculan automáticamente.
A18: Paso 6 | B18: Completar antecedentes específicos: dependencia, hito de compra, N° de requerimiento/licitación/OC, monto, proveedor, próximo hito y riesgo.
A19: Paso 7 | B19: Actualizar el Estado durante la ejecución. Cuando finalice, seleccionar Terminada o Completada.
A20: Paso 8 | B20: Revisar Alerta, Semáforo, Dashboard y Carta Gantt. Estas secciones no requieren cálculo manual.
A22: 3. INSTRUCCIÓN DETALLADA POR COLUMNA – HOJA “PLAN DE TAREAS”
A23: Col. | B23: Campo | C23: Tipo | D23: ¿Quién llena? | E23: Qué se debe ingresar / origen | F23: Ejemplo | G23: Control / efecto | H23: Observación
A24: A | B24: ID | C24: Manual | D24: Usuario | E24: Código único que identifica el proceso o la etapa. No repetir IDs. | F24: CP-001 / CP-001.1 | G24: Permite relacionar y rastrear las actividades. | H24: Use una nomenclatura estable por tipo de gestión.
A25: B | B25: Nivel | C25: Lista | D25: Usuario | E25: Seleccione PROCESO para el trabajo global o ETAPA para una actividad específica. | F25: PROCESO | G25: Determina cómo se calcula el avance. | H25: Un proceso puede contener varias etapas.
A26: C | B26: ID Proceso Padre | C26: Manual | D26: Usuario | E26: En una ETAPA, indique el ID del proceso al que pertenece. En el PROCESO principal se deja vacío. | F26: CP-001 | G26: Es la base del % Participación automática y del avance consolidado. | H26: Debe coincidir exactamente con el ID del proceso principal.
A27: D | B27: Área / Unidad | C27: Lista | D27: Usuario | E27: Seleccione la unidad responsable o relacionada con la gestión. | F27: Bienes y Servicios | G27: Permite clasificar y filtrar el trabajo. | H27: La lista puede ampliarse en Configuracion.
A28: E | B28: Proceso / Proyecto | C28: Manual | D28: Usuario | E28: Nombre general del proceso, proyecto o gestión. | F28: Adquisición de insumos | G28: Agrupa visualmente las actividades. | H28: Mantenga el mismo nombre para todas las etapas del mismo proceso.
A29: F | B29: Etapa / Tarea | C29: Manual | D29: Usuario | E29: Describa claramente la actividad que debe ejecutarse. | F29: Revisar Convenio Marco / Compra Ágil | G29: Es la descripción operativa de la tarea. | H29: Utilice verbos de acción: revisar, elaborar, publicar, recibir, etc.
A30: G | B30: Responsable | C30: Lista | D30: Usuario | E30: Seleccione a la persona, unidad o tercero responsable. | F30: Compras | G30: Permite seguimiento por responsable. | H30: Agregar nuevos responsables en Configuracion.
A31: H | B31: Prioridad | C31: Lista | D31: Usuario | E31: Clasifique la importancia: Crítica, Alta, Media, Baja, etc. | F31: Crítica | G31: Activa colores para facilitar priorización. | H31: Crítica debe reservarse para tareas con impacto relevante.
A32: I | B32: Estado | C32: Lista | D32: Usuario | E32: Actualizar según situación real: No iniciada, En curso, En espera, Bloqueada, Terminada, etc. | F32: En curso | G32: Afecta avance, alertas y semáforo. | H32: Al finalizar use Terminada o Completada.
A33: J | B33: Fecha inicio | C33: Fecha | D33: Usuario | E33: Fecha programada o efectiva de inicio de la actividad. | F33: 26-10-2026 | G33: Se utiliza en duración, avance y Gantt. | H33: Usar fecha real de Excel.
A34: K | B34: Fecha término planificada | C34: Fecha | D34: Usuario | E34: Fecha comprometida o estimada para terminar. | F34: 30-10-2026 | G34: Define vencimiento, días restantes y alertas. | H34: Actualizar solo si existe reprogramación formal.
... A48: Y | B48: Riesgo | C48: Lista | D48: Usuario | E48: Clasifique riesgo de incumplimiento o impacto. | F48: Alto | G48: Apoya priorización preventiva. | H48: Revisar cuando cambien las condiciones.
A50: 4. CÓMO FUNCIONA EL % PARTICIPACIÓN AUTOMÁTICA
A51: Concepto | B51: La columna Q se calcula exclusivamente a partir de la columna C “ID Proceso Padre”. El usuario NO asigna el porcentaje.
A52: Ejemplo 1 | B52: CP-001 tiene CP-001.1 y CP-001.2. Ambas filas indican CP-001 en columna C. Resultado: 50% para cada etapa.
A53: Ejemplo 2 | B53: Se agrega CP-001.3 con padre CP-001. Excel detecta 3 etapas. Resultado: 33,33% para cada una.
A54: Ejemplo 3 | B54: Si CP-001 tiene 5 etapas, cada una representa 20%. Si tiene 10 etapas, cada una representa 10%.
A55: Importante | B55: El ID de la etapa (CP-001.1) por sí solo NO genera la relación. Para que el cálculo funcione, debe indicar CP-001 en la columna C de esa etapa.
A57: 5. EJEMPLO COMPLETO – COMPRA PÚBLICA
A58: ID | B58: Nivel | C58: ID Proceso Padre | D58: Etapa / Tarea | E58: Participación | F58: Estado
A59: CP-001 | B59: PROCESO | D59: Adquisición de insumos | E59: — | F59: En curso
...
